Workbook

Sheet Project type mapping - TEMPLATE
A1: Project Type | B1: Section | C1: Room Type | D1: Unit Type | E1: Category | F1: Brand | G1: Material Type | H1: Default? | I1: Customisable?
A2: Economy | B2: Modular | C2: Wet / Exposed Area | D2: Base Storage | E2: Core Material | F2: GreenPly | G2: BWP | H2: Yes | I2: Yes
A3: Economy | B3: Modular | C3: Dry / Inexposed area | D3: Wall Storage | E3: Core Material | F3: GreenPly | G3: MR | H3: Yes | I3: Yes
A4: Economy | B4: Modular | C4: Dry / Inexposed area | D4: Wardrobe | E4: Core Material | F4: GreenPly | G4: MR | H4: Yes | I4: Yes
A5: Economy | B5: Modular | C5: Dry / Inexposed area | D5: Tall Storage | E5: Core Material | F5: GreenPly | G5: MR | H5: Yes | I5: Yes
A6: Economy | B6: Modular | C6: Wet / Exposed Area | D6: Base Storage | E6: Finish Material | F6: Merino | G6: Smooth Finish | H6: Yes | I6: Yes
A7: Economy | B7: Modular | C7: Dry / Inexposed area | D7: Wall Storage | E7: Finish Material | F7: Merino | G7: Smooth Finish | H7: Yes | I7: Yes
A8: Economy | B8: Modular | C8: Dry / Inexposed area | D8: Tall Storage | E8: Finish Material | F8: Merino | G8: Smooth Finish | H8: Yes | I8: Yes
A9: Economy | B9: Modular | C9: Wet / Exposed Area | D9: Base Storage | E9: Hinges | F9: Hettich | G9: Onsys | H9: Yes | I9: No
A10: Economy | B10: Modular | C10: Dry / Inexposed area | D10: Wall Storage | E10: Hinges | F10: Hettich | G10: Onsys | H10: Yes | I10: No
A11: Economy | B11: Modular | C11: Dry / Inexposed area | D11: Tall Storage | E11: Hinges | F11: Hettich | G11: Onsys | H11: Yes | I11: No
A12: Economy | B12: Modular | C12: Dry / Inexposed area | D12: Wardrobe | E12: Hinges | F12: Hettich | G12: Onsys | H12: Yes | I12: No
... A45: Luxury | B45: Modular | C45: Dry / Inexposed area | D45: Wardrobe | E45: Hinges | F45: Hettich | G45: Onsys | H45: Yes | I45: No

Sheet Economy
A1: Project Type | B1: Section | C1: Room Type | D1: Unit Type | E1: Panel type | F1: Category | G1: Material Type | H1: Brand | I1: DESCRIPTION | J1: Rate | K1: Mark up | L1: Margin | M1: Selling Price
A2: SMOOTH FINISH | I2: Description format : Supply and installation of **Unit Type** with **Core material** **Finish Material****Hinges**
A3: Economy | B3: Modular | C3: Wet / Exposed Area | D3: Base Storage, Wall Storage, Tall Storage, Wardrobe | E3: Carcass/shutter | F3: Core Material, Finish Material, Hinges | G3: Carcass - BWP / Shutter - HDF, Smooth Finish, Soft Close | H3: Carcass - Kit ply Vista Marine / Shutter - Green Panel, Ebco , Sleek , Abhiyam , Catch Plus , Virgo | I3: Supply and installation of Base storage unit with BWP Carcass, HDF Shutter, Smooth finish laminate and soft close hinges | J3: 1475 | K3: 0.25 | L3: =J3*K3 -> 368.75 | M3: =J3+L3 -> 1843.75
I4: Supply and installation of Wall storage unit with BWP Carcass, HDF Shutter, Smooth finish laminate and soft close hinges
I5: Supply and installation of Tall storage unit with BWP Carcass, HDF Shutter, Smooth finish laminate and soft close hinges
I6: Supply and installation of Wardobe unit with BWP Carcass, HDF Shutter, Smooth finish laminate and soft close hinges
C7: Wet / Exposed Area | D7: Base Storage - Inner 1mm, Wall Storage - inner 1mm, Tall Storage - Inner 1mm | E7: Carcass, Shutter | F7: Core Material, Finish Material, Hinges | G7: Carcass - BWP / Shutter - HDF, Smooth Finish , Soft Close | I7: Supply and installation of Base storage - Inner 1mm unit with BWP Carcass, HDF Shutter, Smooth finish laminate and soft close hinges | J7: 1625 | K7: 0.25 | L7: =J7*K7 -> 406.25 | M7: =J7+L7 -> 2031.25
I8: Supply and installation of Wall storage - Inner 1mm unit with BWP Carcass, HDF Shutter, Smooth finish laminate and soft close hinges
I9: Supply and installation of Tall storage - Inner 1mm unit with BWP Carcass, HDF Shutter, Smooth finish laminate and soft close hinges
A10: Economy | B10: Modular | C10: Wet / Exposed Area | D10: Base Storage, Wall Storage, Tall Storage, Wardrobe | E10: Carcass/shutter | F10: Core Material, Finish Material, Hinges | G10: Carcass - BWP / Shutter - Plywood Border with Clear / Tinted Glass , Soft Close, Smooth Finish | H10: Ebco , Sleek , Abhiyam , Catch Plus , Virgo, Carcass / Shutter - Kitply Vist Marine with Glass | I10: Supply and installation of Base storage unit with BWP Carcass, Plywood Border with Clear/Tinted Glass Shutter, Smooth finish laminate and soft close hinges | J10: 1880 | K10: 0.25 | L10: =J10*K10 -> 470 | M10: =J10+L10 -> 2350
I11: Supply and installation of Wall storage unit with BWP Carcass, Plywood Border with Clear/Tinted Glass Shutter, Smooth finish laminate and soft close hinges
I12: Supply and installation of Tall storage unit with BWP Carcass, Plywood Border with Clear/Tinted Glass Shutter, Smooth finish laminate and soft close hinges
I13: Supply and installation of Wardrobe with BWP Carcass, Plywood Border with Clear/Tinted Glass Shutter, Smooth finish laminate and soft close hinges
A14: Economy | B14: Modular | C14: Wet / Exposed Area | D14: Base Storage, Wall Storage, Tall Storage, Wardrobe | E14: Carcass/shutter | F14: Core Material, Finish Material, Hinges | G14: Carcass - BWP / Shutter - Plywood Border with Fluted Glass , Smooth Finish , Soft Close | H14: Ebco , Sleek , Abhiyam , Catch Plus , Virgo, Carcass / Shutter - Kitply Vist Marine with Glass | I14: Supply and installation of Base storage unit with BWP Carcass, Plywood Border with Fluted Glass Shutter, Smooth finish laminate and soft close hinges | J14: 2000 | K14: 0.25 | L14: =J14*K14 -> 500 | M14: =J14+L14 -> 2500
I15: Supply and installation of Wall storage unit with BWP Carcass, Plywood Border with Fluted Glass Shutter, Smooth finish laminate and soft close hinges
I16: Supply and installation of Tall storage unit with BWP Carcass, Plywood Border with Fluted Glass Shutter, Smooth finish laminate and soft close hinges
I17: Supply and installation of Wardrobe with BWP Carcass, Plywood Border with Fluted Glass Shutter, Smooth finish laminate and soft close hinges
A18: Economy | B18: Modular | C18: Wet / Exposed Area | D18: Base Storage, Wall Storage, Tall Storage, Wardrobe | E18: Carcass/shutter | F18: Core Material, Finish Material, Hinges | G18: Carcass - BWP / Shutter - Black / Silver colour Aluminium Profile with Clear or Tinted Glass, Smooth Finish , Soft Close | H18: Sleek , Ebco, Abhiyam , Catch Plus , Virgo, Carcass -Kitply Vista Marine / Shutter - Imported Aluminium Profile Shutters | I18: Supply and installation of Base storage unit with BWP Carcass, Aluminium Profile with Clear/Tinted Glass Shutter, Smooth finish laminate and soft close hinges | J18: 2325 | K18: 0.25 | L18: =J18*K18 -> 581.25 | M18: =J18+L18 -> 2906.25
I19: Supply and installation of Wall storage unit with BWP Carcass, Aluminium Profile with Clear/Tinted Glass Shutter, Smooth finish laminate and soft close hinges
I20: Supply and installation of Tall storage unit with BWP Carcass, Aluminium Profile with Clear/Tinted Glass Shutter, Smooth finish laminate and soft close hinges
I21: Supply and installation of Wardrobe with BWP Carcass, Aluminium Profile with Clear/Tinted Glass Shutter, Smooth finish laminate and soft close hinges
A22: Economy | B22: Modular | C22: Wet / Exposed Area | D22: Base Storage, Wall Storage, Tall Storage, Wardrobe | E22: Carcass/shutter | F22: Core Material, Finish Material, Hinges | G22: Carcass - BWP / Shutter - Black / Silver colour Aluminium Profile with Fluted Glass, Smooth Finish , Soft Close | H22: Sleek , Ebco, Abhiyam , Catch Plus , Virgo, Carcass -Kitply Vista Marine / Shutter - Imported Aluminium Profile Shutters | J22: 2425 | K22: 0.25 | L22: =J22*K22 -> 606.25 | M22: =J22+L22 -> 3031.25
A23: Economy | B23: Modular | C23: Wet / Exposed Area | D23: Base Storage, Wall Storage, Tall Storage, Wardrobe | E23: Carcass/shutter | F23: Core Material, Finish Material, Hinges | G23: Carcass - BWP / Shutter - Gold / Rose Gold colour Aluminium Profile with Clear or Tinted Glass, Soft Close, Smooth Finish | H23: Sleek , Ebco, Abhiyam , Catch Plus , Virgo, Carcass -Kitply Vista Marine / Shutter - Imported Aluminium Profile Shutters | J23: 2425 | K23: 0.25 | L23: =J23*K23 -> 606.25 | M23: =J23+L23 -> 3031.25
A24: Economy | B24: Modular | C24: Wet / Exposed Area | D24: Base Storage, Wall Storage, Tall Storage, Wardrobe | E24: Carcass/shutter | F24: Core Material, Finish Material, Hinges | G24: Carcass - BWP / Shutter - Gold / Rose Gold colour Aluminium Profile with Fluted Glass, Smooth Finish , Soft Close | H24: Sleek , Ebco, Abhiyam , Catch Plus , Virgo, Carcass -Kitply Vista Marine / Shutter - Imported Aluminium Profile Shutters | J24: 2525 | K24: 0.25 | L24: =J24*K24 -> 631.25 | M24: =J24+L24 -> 3156.25
A25: Economy | B25: Modular | C25: Wet / Exposed Area | D25: Base Storage, Wall Storage, Tall Storage, Wardrobe | E25: Carcass/shutter | F25: Core Material, Finish Material, Hinges | G25: Carcass Inner 1mm- BWP / Shutter - Plywood Border with Clear / Tinted Glass , Smooth Finish , Soft Close | H25: Ebco , Sleek , Abhiyam , Catch Plus , Virgo, Carcass / Shutter - Kitply Vist Marine with Glass | J25: 2130 | K25: 0.25 | L25: =J25*K25 -> 532.5 | M25: =J25+L25 -> 2662.5
A26: Economy | B26: Modular | C26: Wet / Exposed Area | D26: Base Storage, Wall Storage, Tall Storage, Wardrobe | E26: Carcass/shutter | F26: Core Material, Finish Material, Hinges | G26: Carcass inner 1mm - BWP / Shutter - Plywood Border with Fluted Glass , Smooth Finish , Soft Close | H26: Ebco , Sleek , Abhiyam , Catch Plus , Virgo, Carcass / Shutter - Kitply Vist Marine with Glass | J26: 2230 | K26: 0.25 | L26: =J26*K26 -> 557.5 | M26: =J26+L26 -> 2787.5
A27: Economy | B27: Modular | C27: Wet / Exposed Area | D27: Base Storage, Wall Storage, Tall Storage, Wardrobe | E27: Carcass/shutter | F27: Core Material, Finish Material, Hinges | G27: Carcass Inner 1mm- BWP / Shutter - Black / Silver colour Aluminium Profile with Clear or Tinted Glass , Smooth Finish , Soft Close | H27: Sleek , Ebco, Abhiyam , Catch Plus , Virgo, Carcass -Kitply Vista Marine / Shutter - Imported Aluminium Profile Shutters | J27: 2475 | K27: 0.25 | L27: =J27*K27 -> 618.75 | M27: =J27+L27 -> 3093.75
A28: Economy | B28: Modular | C28: Wet / Exposed Area | D28: Base Storage, Wall Storage, Tall Storage, Wardrobe | E28: Carcass/shutter | F28: Core Material, Finish Material, Hinges | G28: Carcass Inner 1mm - BWP / Shutter - Black / Silver colour Aluminium Profile with Fluted Glass, Smooth Finish , Soft Close | H28: Sleek , Ebco, Abhiyam , Catch Plus , Virgo, Carcass -Kitply Vista Marine / Shutter - Imported Aluminium Profile Shutters | J28: 2575 | K28: 0.25 | L28: =J28*K28 -> 643.75 | M28: =J28+L28 -> 3218.75
A29: Economy | B29: Modular | C29: Wet / Exposed Area | D29: Base Storage, Wall Storage, Tall Storage, Wardrobe | E29: Carcass/shutter | F29: Core Material, Finish Material, Hinges | G29: Carcass Inner 1mm - BWP / Shutter - Gold / Rose Gold colour Aluminium Profile with Fluted Glass, Smooth Finish , Soft Close | H29: Sleek , Ebco, Abhiyam , Catch Plus , Virgo, Carcass -Kitply Vista Marine / Shutter - Imported Aluminium Profile Shutters | J29: 2575 | K29: 0.25 | L29: =J29*K29 -> 643.75 | M29: =J29+L29 -> 3218.75
A30: Economy | B30: Modular | C30: Wet / Exposed Area | D30: Base Storage, Wall Storage, Tall Storage, Wardrobe | E30: Carcass/shutter | F30: Core Material, Finish Material, Hinges | G30: Carcass Inner 1mm- BWP / Shutter - Gold / Rose Gold colour Aluminium Profile with Clear or Tinted Glass, Smooth Finish , Soft Close | H30: Sleek , Ebco, Abhiyam , Catch Plus , Virgo, Carcass -Kitply Vista Marine / Shutter - Imported Aluminium Profile Shutters | J30: 2675 | K30: 0.25 | L30: =J30*K30 -> 668.75 | M30: =J30+L30 -> 3343.75
A31: Economy | B31: Modular | C31: Wet / Exposed Area | D31: Curved Shape Base Storage unit | E31: Carcass/shutter | F31: Core Material, Finish Material, Hinges | G31: Carcass - BWP / Shutter - HDF, Smooth Finish , Soft Close | H31: Carcass - Kit ply Vista Marine / Shutter - Green Panel, Ebco , Sleek , Abhiyam , Catch Plus , Virgo | J31: 1850 | K31: 0.25 | L31: =J31*K31 -> 462.5 | M31: =J31+L31 -> 2312.5
A32: Economy | B32: Modular | C32: Wet / Exposed Area | D32: Curved Shape Drawer Storage unit | E32: Carcass/shutter | F32: Core Material, Finish Material | G32: Carcass - BWP / Shutter - HDF, Smooth Finish | H32: Carcass - Kit ply Vista Marine / Shutter - Green Panel, Catch Plus , Virgo , Abhiyam | J32: 1850 | K32: 0.25 | L32: =J32*K32 -> 462.5 | M32: =J32+L32 -> 2312.5
A33: Economy | B33: Modular | C33: Wet / Exposed Area | D33: Open Unit - Inner 0.8mm | E33: Carcass | F33: Core Material, Finish Material | G33: CARCASS - BWP, Smooth Finish | H33: Carcass - Kit ply Vista Marine, Abhiyam, Catch Plus , Virgo | I33: Supply and installation of Open unit - Inner 0.8mm with BWP Carcass and Smooth finish laminate | J33: 1250 | K33: 0.25 | L33: =J33*K33 -> 312.5 | M33: =J33+L33 -> 1562.5
A34: Economy | B34: Modular | C34: Wet / Exposed Area | D34: Open Unit - Inner 1mm | E34: Carcass | F34: Core Material, Finish Material | G34: CARCASS - BWP, Smooth Finish | H34: Carcass - Kit ply Vista Marine, Abhiyam, Catch Plus , Virgo | I34: Supply and installation of Open unit - Inner 1mm with BWP Carcass and Smooth finish laminate | J34: 1475 | K34: 0.25 | L34: =J34*K34 -> 368.75 | M34: =J34+L34 -> 1843.75
A35: Economy | B35: Modular | C35: Wet / Exposed Area | D35: Loft | E35: Frame and Shutter | F35: Core Material, Finish Material, Hinges | G35: Smooth Finish, Soft Close, Frame - BWP / Shutter - HDF | H35: Ebco , Sleek , Abhiyam , Catch Plus , Virgo, Frame- Kit ply Vista Marine / Shutter - Green Panel, Fortune gold | J35: 872 | K35: 0.25 | L35: =J35*K35 -> 218 | M35: =J35+L35 -> 1090
A36: Economy | B36: Modular | C36: Wet / Exposed Area | D36: Ledge | E36: Ledge -25mm | F36: Finish Material, Core Material | G36: Smooth Finish , CARCASS - BWP | H36: Ledge - Kit Ply Vista Marine, Abhiyam , Catch Plus , Virgo | J36: 758 | K36: 0.25 | L36: =J36*K36 -> 189.5 | M36: =J36+L36 -> 947.5
A37: Economy | B37: Modular | C37: Wet / Exposed Area | D37: Ledge | E37: Ledge -36mm | F37: Finish Material, Core Material | G37: Smooth Finish , CARCASS - BWP | H37: Ledge - Kit Ply Vista Marine, Abhiyam , Catch Plus , Virgo | J37: 758 | K37: 0.25 | L37: =J37*K37 -> 189.5 | M37: =J37+L37 -> 947.5
A38: Economy | B38: Modular | C38: Wet / Exposed Area | D38: Ledge | E38: Ledge -50mm | F38: Finish Material, Core Material | G38: Smooth Finish , CARCASS - BWP | H38: Ledge - Kit Ply Vista Marine, Abhiyam , Catch Plus , Virgo | J38: 958 | K38: 0.25 | L38: =J38*K38 -> 239.5 | M38: =J38+L38 -> 1197.5
A39: Economy | B39: Modular | C39: Wet / Exposed Area | D39: Partition | E39: Partition -75mm | F39: Finish Material, Core Material | G39: Smooth Finish , CARCASS - BWP | H39: Kit Ply Vista Marine , Abhiyam , Catch Plus , Virgo | J39: 1575 | K39: 0.25 | L39: =J39*K39 -> 393.75 | M39: =J39+L39 -> 1968.75
A40: Economy | B40: Modular | C40: Wet / Exposed Area | D40: Panel | E40: Curved Shape Panel | F40: Finish Material, Core Material | G40: Smooth Finish , CARCASS - BWP | H40: Kit Ply Vista Marine, Catch Plus , Abhiyam , Virgo | J40: 1025 | K40: 0.25 | L40: =J40*K40 -> 256.25 | M40: =J40+L40 -> 1281.25
...

Sheet Lite Premium
A1: Project Type | B1: Section | C1: Room Type | D1: Unit Type | E1: Panel type | F1: Category | G1: Material Type | H1: Brand | I1: Description | J1: Rate | K1: Mark up | L1: Margin | M1: Selling Price
A2: SMOOTH FINISH
A3: Mid Premium | B3: Modular | C3: Wet / Exposed Area | D3: Base Storage, Wall Storage, Tall Storage, Wardrobe | E3: Carcass/shutter | F3: Core Material, Finish Material, Hinges | G3: Carcass - BWP / Shutter - HDHMR, Smooth Finish, Soft Close | H3: Carcass - Century Sainik or Green Absolute / Shutter - Green Panel, Hettich Onsys , , Advance , New Mika , Rotolam | J3: =J32+100 -> 1600 | K3: 0.25 | L3: =J3*K3 -> 400 | M3: =J3+L3 -> 2000
A4: Mid Premium | B4: Modular | C4: Wet / Exposed Area | D4: Base Storage - Inner 1mm, Wall Storage - inner 1mm, Tall Storage - Inner 1mm | E4: Carcass, Shutter | F4: Core Material, Finish Material, Hinges | G4: Carcass - BWP / Shutter - HDHMR, Smooth Finish, Soft Close | H4: Carcass - Century Sainik or Green Absolute / Shutter - Green Panel, Hettich Onsys , , Advance , New Mika , Rotolam | I4: Supply and installation of Base storage - Inner 1mm unit with BWP Carcass, HDHMR Shutter, Smooth finish laminate and soft close hinges | J4: =J36+100 -> 1750 | K4: 0.25 | L4: =J4*K4 -> 437.5 | M4: =J4+L4 -> 2187.5
H5: Carcass - Century Sainik or Green Absolute / Shutter - Green Panel, Hettich Onsys , , Advance , New Mika , Rotolam | I5: Supply and installation of Wall storage - Inner 1mm unit with BWP Carcass, HDHMR Shutter, Smooth finish laminate and soft close hinges
H6: Carcass - Century Sainik or Green Absolute / Shutter - Green Panel, Hettich Onsys , , Advance , New Mika , Rotolam | I6: Supply and installation of Tall storage - Inner 1mm unit with BWP Carcass, HDHMR Shutter, Smooth finish laminate and soft close hinges
A7: Mid Premium | B7: Modular | C7: Wet / Exposed Area | D7: Base Storage, Wall Storage, Tall Storage, Wardrobe | E7: Carcass/shutter | F7: Core Material, Finish Material, Hinges | G7: Carcass - BWP / Shutter - Plywood Border with Clear / Tinted Glass , Soft Close, Smooth Finish | H7: Hettich Onsys , , Advance , New Mika , Rotolam, Carcass / Shutter - Century Sainik or Green Absolute with Glass | J7: =J39+100 -> 2005 | K7: 0.25 | L7: =J7*K7 -> 501.25 | M7: =J7+L7 -> 2506.25
A8: Mid Premium | B8: Modular | C8: Wet / Exposed Area | D8: Base Storage, Wall Storage, Tall Storage, Wardrobe | E8: Carcass/shutter | F8: Core Material, Finish Material, Hinges | G8: Carcass - BWP / Shutter - Plywood Border with Fluted Glass , Smooth Finish , Soft Close | H8: Hettich Onsys , , Advance , New Mika , Rotolam, Carcass / Shutter - Century Sainik or Green Absolute with Glass | J8: =J40+100 -> 2125 | K8: 0.25 | L8: =J8*K8 -> 531.25 | M8: =J8+L8 -> 2656.25
A9: Mid Premium | B9: Modular | C9: Wet / Exposed Area | D9: Base Storage, Wall Storage, Tall Storage, Wardrobe | E9: Carcass/shutter | F9: Core Material, Finish Material, Hinges | G9: Carcass - BWP / Shutter - Black / Silver colour Aluminium Profile with Clear or Tinted Glass, Smooth Finish , Soft Close | H9: , Hettich Onsys, Advance , New Mika , Rotolam, Carcass -Century Sainik or Green Absolute / Shutter - CNR Aluminium Profile Shutters | J9: =J41+100 -> 2450 | K9: 0.25 | L9: =J9*K9 -> 612.5 | M9: =J9+L9 -> 3062.5
A10: Mid Premium | B10: Modular | C10: Wet / Exposed Area | D10: Base Storage, Wall Storage, Tall Storage, Wardrobe | E10: Carcass/shutter | F10: Core Material, Finish Material, Hinges | G10: Carcass - BWP / Shutter - Black / Silver colour Aluminium Profile with Fluted Glass, Smooth Finish , Soft Close | H10: , Hettich Onsys, Advance , New Mika , Rotolam, Carcass -Century Sainik or Green Absolute / Shutter - CNR Aluminium Profile Shutters | J10: =J42+100 -> 2550 | K10: 0.25 | L10: =J10*K10 -> 637.5 | M10: =J10+L10 -> 3187.5
A11: Mid Premium | B11: Modular | C11: Wet / Exposed Area | D11: Base Storage, Wall Storage, Tall Storage, Wardrobe | E11: Carcass/shutter | F11: Core Material, Finish Material, Hinges | G11: Carcass - BWP / Shutter - Gold / Rose Gold colour Aluminium Profile with Clear or Tinted Glass, Soft Close, Smooth Finish | H11: , Hettich Onsys, Advance , New Mika , Rotolam, Carcass -Century Sainik or Green Absolute / Shutter - CNR Aluminium Profile Shutters | J11: =J43+100 -> 2550 | K11: 0.25 | L11: =J11*K11 -> 637.5 | M11: =J11+L11 -> 3187.5
A12: Mid Premium | B12: Modular | C12: Wet / Exposed Area | D12: Base Storage, Wall Storage, Tall Storage, Wardrobe | E12: Carcass/shutter | F12: Core Material, Finish Material, Hinges | G12: Carcass - BWP / Shutter - Gold/ Rose Gold Aluminium Profile with Clear or Tinted Glass | H12: , Hettich Onsys, Advance , New Mika , Rotolam, Carcass -Century Sainik or Green Absolute / Shutter - CNR Aluminium Profile Shutters | J12: =J44+100 -> 2650 | K12: 0.25 | L12: =J12*K12 -> 662.5 | M12: =J12+L12 -> 3312.5
A13: Mid Premium | B13: Modular | C13: Wet / Exposed Area | D13: Base Storage, Wall Storage, Tall Storage, Wardrobe | E13: Carcass/shutter | F13: Core Material, Finish Material, Hinges | G13: Carcass Inner 1mm- BWP / Shutter - Plywood Border with Clear / Tinted Glass , Smooth Finish , Soft Close | H13: Hettich Onsys , , Advance , New Mika , Rotolam, Carcass / Shutter - Century Sainik or Green Absolute with Glass | J13: =J45+100 -> 2130 | K13: 0.25 | L13: =J13*K13 -> 532.5 | M13: =J13+L13 -> 2662.5
A14: Mid Premium | B14: Modular | C14: Wet / Exposed Area | D14: Base Storage, Wall Storage, Tall Storage, Wardrobe | E14: Carcass/shutter | F14: Core Material, Finish Material, Hinges | G14: Carcass inner 1mm - BWP / Shutter - Plywood Border with Fluted Glass , Smooth Finish , Soft Close | H14: Hettich Onsys , , Advance , New Mika , Rotolam, Carcass / Shutter - Century Sainik or Green Absolute with Glass | J14: =J46+100 -> 2250 | K14: 0.25 | L14: =J14*K14 -> 562.5 | M14: =J14+L14 -> 2812.5
A15: Mid Premium | B15: Modular | C15: Wet / Exposed Area | D15: Base Storage, Wall Storage, Tall Storage, Wardrobe | E15: Carcass/shutter | F15: Core Material, Finish Material, Hinges | G15: Carcass Inner 1mm- BWP / Shutter - Black / Silver colour Aluminium Profile with Clear or Tinted Glass , Smooth Finish , Soft Close | H15: , Hettich Onsys, Advance , New Mika , Rotolam, Carcass -Century Sainik or Green Absolute / Shutter - CNR Aluminium Profile Shutters | J15: =J47+100 -> 2600 | K15: 0.25 | L15: =J15*K15 -> 650 | M15: =J15+L15 -> 3250
A16: Mid Premium | B16: Modular | C16: Wet / Exposed Area | D16: Base Storage, Wall Storage, Tall Storage, Wardrobe | E16: Carcass/shutter | F16: Core Material, Finish Material, Hinges | G16: Carcass Inner 1mm - BWP / Shutter - Black / Silver colour Aluminium Profile with Fluted Glass, Smooth Finish , Soft Close | H16: , Hettich Onsys, Advance , New Mika , Rotolam, Carcass -Century Sainik or Green Absolute / Shutter - CNR Aluminium Profile Shutters | J16: =J48+100 -> 2700 | K16: 0.25 | L16: =J16*K16 -> 675 | M16: =J16+L16 -> 3375
A17: Mid Premium | B17: Modular | C17: Wet / Exposed Area | D17: Base Storage, Wall Storage, Tall Storage, Wardrobe | E17: Carcass/shutter | F17: Core Material, Finish Material, Hinges | G17: Carcass Inner 1mm- BWP / Shutter - Gold / Rose Gold colour Aluminium Profile with Clear or Tinted Glass, Smooth Finish , Soft Close | H17: , Hettich Onsys, Advance , New Mika , Rotolam, Carcass -Century Sainik or Green Absolute / Shutter - CNR Aluminium Profile Shutters | J17: =J52+100 -> 2700 | K17: 0.25 | L17: =J17*K17 -> 675 | M17: =J17+L17 -> 3375
A18: Mid Premium | B18: Modular | C18: Wet / Exposed Area | D18: Base Storage, Wall Storage, Tall Storage, Wardrobe | E18: Carcass/shutter | F18: Core Material, Finish Material, Hinges | G18: Carcass Inner 1mm - BWP / Shutter - Gold / Rose Gold colour Aluminium Profile with Fluted Glass, Smooth Finish , Soft Close | H18: , Hettich Onsys, Advance , New Mika , Rotolam, Carcass -Century Sainik or Green Absolute / Shutter - CNR Aluminium Profile Shutters | J18: =J53+100 -> 2800 | K18: 0.25 | L18: =J18*K18 -> 700 | M18: =J18+L18 -> 3500
A19: Mid Premium | B19: Modular | C19: Wet / Exposed Area | D19: Curved Shape Base Storage unit | E19: Carcass/shutter | F19: Core Material, Finish Material, Hinges | G19: Carcass - BWP / Shutter - HDHMR, Smooth Finish , Soft Close | H19: Carcass - Century Sainik or Green Absolute / Shutter - Green Panel, Hettich Onsys , , Advance , New Mika , Rotolam | J19: =J54+100 -> 1975 | K19: 0.25 | L19: =J19*K19 -> 493.75 | M19: =J19+L19 -> 2468.75
A20: Mid Premium | B20: Modular | C20: Wet / Exposed Area | D20: Curved Shape Drawer Storage unit | E20: Carcass/shutter | F20: Core Material, Finish Material | G20: Carcass - BWP / Shutter - HDHMR, Smooth Finish | H20: Carcass - Century Sainik or Green Absolute / Shutter - Green Panel, New Mika , Rotolam , Advance | J20: =J55+100 -> 1975 | K20: 0.25 | L20: =J20*K20 -> 493.75 | M20: =J20+L20 -> 2468.75
A21: Mid Premium | B21: Modular | C21: Wet / Exposed Area | D21: Tambour Storage | E21: Carcass | F21: Core Material, Finish Material | G21: CARCASS - BWP, Smooth Finish | H21: Carcass - Century Sainik or Green Absolute, Advance, New Mika , Rotolam | J21: =J56+100 -> 1375 | K21: 0.25 | L21: =J21*K21 -> 343.75 | M21: =J21+L21 -> 1718.75
A22: Mid Premium | B22: Modular | C22: Wet / Exposed Area | D22: Open Unit - Inner 1mm | E22: Carcass | F22: Core Material, Finish Material | G22: CARCASS - BWP, Smooth Finish | H22: Carcass - Century Sainik or Green Absolute, Advance, New Mika , Rotolam | J22: =J57+100 -> 1600 | K22: 0.25 | L22: =J22*K22 -> 400 | M22: =J22+L22 -> 2000
A23: Mid Premium | B23: Modular | C23: Wet / Exposed Area | D23: Loft | E23: Frame and Shutter | F23: Core Material, Finish Material, Hinges | G23: Smooth Finish, Soft Close, Frame - BWP / Shutter - HDHMR | H23: Hettich Onsys , , Advance , New Mika , Rotolam, Frame- Century Sainik or Green Absolute / Shutter - Green Panel, | J23: =J58+100 -> 997 | K23: 0.25 | L23: =J23*K23 -> 249.25 | M23: =J23+L23 -> 1246.25
A24: Mid Premium | B24: Modular | C24: Wet / Exposed Area | D24: Ledge | E24: Ledge -25mm | F24: Finish Material, Core Material | G24: Smooth Finish , CARCASS - BWP | H24: Ledge - Century Sainik or Green Absolute, Advance , New Mika , Rotolam | J24: =J59+100 -> 883 | K24: 0.25 | L24: =J24*K24 -> 220.75 | M24: =J24+L24 -> 1103.75
A25: Mid Premium | B25: Modular | C25: Wet / Exposed Area | D25: Ledge | E25: Ledge -36mm | F25: Finish Material, Core Material | G25: Smooth Finish , CARCASS - BWP | H25: Ledge - Century Sainik or Green Absolute, Advance , New Mika , Rotolam | J25: =J60+100 -> 883 | K25: 0.25 | L25: =J25*K25 -> 220.75 | M25: =J25+L25 -> 1103.75
A26: Mid Premium | B26: Modular | C26: Wet / Exposed Area | D26: Ledge | E26: Ledge -50mm | F26: Finish Material, Core Material | G26: Smooth Finish , CARCASS - BWP | H26: Ledge - Century Sainik or Green Absolute, Advance , New Mika , Rotolam | J26: =J61+100 -> 1083 | K26: 0.25 | L26: =J26*K26 -> 270.75 | M26: =J26+L26 -> 1353.75
A27: Mid Premium | B27: Modular | C27: Wet / Exposed Area | D27: Partition | E27: Partition -75mm | F27: Finish Material, Core Material | G27: Smooth Finish , CARCASS - BWP | H27: Century Sainik or Green Absolute , Advance , New Mika , Rotolam | J27: =J62+100 -> 1700 | K27: 0.25 | L27: =J27*K27 -> 425 | M27: =J27+L27 -> 2125
A28: Mid Premium | B28: Modular | C28: Wet / Exposed Area | D28: Panel | E28: Curved Shape Panel | F28: Finish Material, Core Material | G28: Smooth Finish , CARCASS - BWP | H28: Century Sainik or Green Absolute, New Mika , Advance , Rotolam | J28: =J63+100 -> 1150 | K28: 0.25 | L28: =J28*K28 -> 287.5 | M28: =J28+L28 -> 1437.5
A29: Mid Premium | B29: Modular | C29: Wet / Exposed Area | D29: Panel | E29: Wallpanel , pelmet , Base panel / Side panel , Jam Panel, Chimney Panel | F29: Finish Material, Core Material | G29: Smooth Finish , CARCASS - BWP | H29: Century Sainik or Green Absolute, New Mika , Advance , Rotolam | J29: =J64+100 -> 1000 | K29: 0.25 | L29: =J29*K29 -> 250 | M29: =J29+L29 -> 1250
A30: Mid Premium | B30: Modular | C30: Wet / Exposed Area | D30: Panel | E30: Ceiling Panel | F30: Finish Material, Core Material | G30: Smooth Finish , CARCASS - BWP | H30: Century Sainik or Green Absolute, New Mika , Advance , Rotolam | J30: =J69+100 -> 1167 | K30: 0.25 | L30: =J30*K30 -> 291.75 | M30: =J30+L30 -> 1458.75
K31: 0.25 | L31: =J31*K31 -> 0
A32: Mid Premium | B32: Modular | C32: Dry / Inexposed area | D32: Base Storage, Wall Storage, Tall Storage, Wardrobe | E32: Carcass/shutter | F32: Core Material, Finish Material, Hinges | G32: Smooth Finish, Soft Close, Carcass - MR / Shutter - HDHMR | H32: Carcass - Century Sainik or Greenply Absolute / Shutter - Green Panel, Hettich Onsys , , New Mika , Advance , Rotolam | I32: Supply and installation of Base storage with MR Carcass, HDHMR Shutter, Smooth finish laminate and soft close hinges | J32: 1500 | K32: 0.25 | L32: =J32*K32 -> 375 | M32: =J32+L32 -> 1875
I33: Supply and installation of Wall storage with MR Carcass, HDHMR Shutter, Smooth finish laminate and soft close hinges
I34: Supply and installation of Tall storage with MR Carcass, HDHMR Shutter, Smooth finish laminate and soft close hinges
I35: Supply and installation of Wardrobe with MR Carcass, HDHMR Shutter, Smooth finish laminate and soft close hinges
A36: Mid Premium | B36: Modular | C36: Dry / Inexposed area | D36: Base Storage - Inner 1mm, Wall Storage - inner 1mm, Tall Storage - Inner 1mm | E36: Carcass, Shutter | F36: Core Material, Finish Material, Hinges | G36: Carcass - BWP / Shutter - HDHMR, Smooth Finish, Soft Close | H36: Carcass - Century Sainik or Green Absolute / Shutter - Green Panel, Hettich Onsys , , Advance , New Mika , Rotolam | I36: Supply and installation of Base storage - Inner 1mm unit with BWP Carcass, HDHMR Shutter, Smooth finish laminate and soft close hinges | J36: 1650 | K36: 0.25 | L36: =J36*K36 -> 412.5 | M36: =J36+L36 -> 2062.5
H37: Carcass - Century Sainik or Green Absolute / Shutter - Green Panel, Hettich Onsys , , Advance , New Mika , Rotolam | I37: Supply and installation of Wall storage - Inner 1mm unit with BWP Carcass, HDHMR Shutter, Smooth finish laminate and soft close hinges
H38: Carcass - Century Sainik or Green Absolute / Shutter - Green Panel, Hettich Onsys , , Advance , New Mika , Rotolam | I38: Supply and installation of Tall storage - Inner 1mm unit with BWP Carcass, HDHMR Shutter, Smooth finish laminate and soft close hinges
A39: Mid Premium | B39: Modular | C39: Dry / Inexposed area | D39: Base Storage, Wall Storage, Tall Storage, Wardrobe | E39: Carcass/shutter | F39: Core Material, Finish Material, Hinges | G39: Carcass - MR/ Shutter - Plywood Border with Clear / Tinted Glass , Smooth Finish , Soft Close | H39: Carcass - Century Sainik or Greenply Absolute / Shutter - Green Panel, Hettich Onsys , , New Mika , Advance , Rotolam | J39: 1905 | K39: 0.25 | L39: =J39*K39 -> 476.25 | M39: =J39+L39 -> 2381.25
A40: Mid Premium | B40: Modular | C40: Dry / Inexposed area | D40: Base Storage, Wall Storage, Tall Storage, Wardrobe | E40: Carcass/shutter | F40: Core Material, Finish Material, Hinges | G40: Carcass - MR / Shutter - Ply wood border with Fluted Glass , Smooth Finish , Soft Close | H40: Hettich Onsys , , Advance , New Mika , Rotolam, Carcass - Century Sainik or Green Absolute / Shutter - Green Panel with Glass | J40: 2025 | K40: 0.25 | L40: =J40*K40 -> 506.25 | M40: =J40+L40 -> 2531.25
...

Sheet Premium
A1: Project Type | B1: Section | C1: Room Type | D1: Unit Type | E1: Panel type | F1: Category | G1: Material Type | H1: Brand | I1: Description | J1: Rate | K1: Hinges rate | L1: Basic Value | M1: Mark up | N1: Margin | O1: Selling Price
A2: SMOOTH FINISH
A3: Mid Premium | B3: Modular | C3: Wet / Exposed Area | D3: Base Storage, Wall Storage, Tall Storage, Wardrobe | E3: Carcass/shutter | F3: Core Material, Finish Material, Hinges | G3: Carcass - BWP / Shutter - HDHMR Boilo, Smooth Finish, Soft Close | H3: Carcass - Century Bond or Green OptimaG / Shutter - Action TESA, Hettich Veyosis or Hafele Eqv , , Greenlam , Century lam , Merino | I3: Supply and installation of Base storage unit with BWP Carcass, HDHMR Boilo Shutter, Smooth finish laminate and soft close hinges | J3: 1715 | L3: =J3+K3 -> 1715 | M3: 0.25 | N3: =L3*M3 -> 428.75 | O3: =L3+N3 -> 2143.75
I4: Supply and installation of Wall storage unit with BWP Carcass, HDHMR Boilo Shutter, Smooth finish laminate and soft close hinges
I5: Supply and installation of Tall storage unit with BWP Carcass, HDHMR Boilo Shutter, Smooth finish laminate and soft close hinges
I6: Supply and installation of Wardrobe with BWP Carcass, HDHMR Boilo Shutter, Smooth finish laminate and soft close hinges
A7: Mid Premium | B7: Modular | C7: Wet / Exposed Area | D7: Base Storage, Wall Storage, Tall Storage, Wardrobe | E7: Carcass/shutter | F7: Core Material, Finish Material, Hinges | G7: Carcass - BWP / Shutter - Plywood Border with Clear / Tinted Glass , Soft Close, Smooth Finish | H7: Hettich Veyosis or Hafele Eqv , , Greenlam , Century lam , Merino, Carcass / Shutter - Century Bond or Green OptimaG with Glass | J7: 2095 | L7: =J7+K7 -> 2095 | M7: 0.25 | N7: =L7*M7 -> 523.75 | O7: =L7+N7 -> 2618.75
A8: Mid Premium | B8: Modular | C8: Wet / Exposed Area | D8: Base Storage, Wall Storage, Tall Storage, Wardrobe | E8: Carcass/shutter | F8: Core Material, Finish Material, Hinges | G8: Carcass - BWP / Shutter - Plywood Border with Fluted Glass , Smooth Finish , Soft Close | H8: Hettich Veyosis or Hafele Eqv , , Greenlam , Century lam , Merino, Carcass / Shutter - Century Bond or Green OptimaG with Glass | J8: 2215 | L8: =J8+K8 -> 2215 | M8: 0.25 | N8: =L8*M8 -> 553.75 | O8: =L8+N8 -> 2768.75
A9: Mid Premium | B9: Modular | C9: Wet / Exposed Area | D9: Base Storage, Wall Storage, Tall Storage, Wardrobe | E9: Carcass/shutter | F9: Core Material, Finish Material, Hinges | G9: Carcass - BWP / Shutter - Black / Silver colour Aluminium Profile with Clear or Tinted Glass, Smooth Finish , Soft Close | H9: , Hettich Veyosis or Hafele Eqv, Greenlam , Century lam , Merino, Carcass -Century Bond or Green OptimaG / Shutter - CNR Aluminium Profile Shutters | J9: 2250 | L9: =J9+K9 -> 2250 | M9: 0.25 | N9: =L9*M9 -> 562.5 | O9: =L9+N9 -> 2812.5
A10: Mid Premium | B10: Modular | C10: Wet / Exposed Area | D10: Base Storage, Wall Storage, Tall Storage, Wardrobe | E10: Carcass/shutter | F10: Core Material, Finish Material, Hinges | G10: Carcass - BWP / Shutter - Black / Silver colour Aluminium Profile with Fluted Glass, Smooth Finish , Soft Close | H10: , Hettich Veyosis or Hafele Eqv, Greenlam , Century lam , Merino, Carcass -Century Bond or Green OptimaG / Shutter - CNR Aluminium Profile Shutters | J10: 2350 | L10: =J10+K10 -> 2350 | M10: 0.25 | N10: =L10*M10 -> 587.5 | O10: =L10+N10 -> 2937.5
A11: Mid Premium | B11: Modular | C11: Wet / Exposed Area | D11: Base Storage, Wall Storage, Tall Storage, Wardrobe | E11: Carcass/shutter | F11: Core Material, Finish Material, Hinges | G11: Carcass - BWP / Shutter - / Rose colour Aluminium Profile with Clear or Tinted Glass, Soft Close, Smooth Finish | H11: , Hettich Veyosis or Hafele Eqv, Greenlam , Century lam , Merino, Carcass -Century Bond or Green OptimaG / Shutter - CNR Aluminium Profile Shutters | J11: 2350 | L11: =J11+K11 -> 2350 | M11: 0.25 | N11: =L11*M11 -> 587.5 | O11: =L11+N11 -> 2937.5
A12: Mid Premium | B12: Modular | C12: Wet / Exposed Area | D12: Base Storage, Wall Storage, Tall Storage, Wardrobe | E12: Carcass/shutter | F12: Core Material, Finish Material, Hinges | G12: Carcass - BWP / Shutter - / Rose colour Aluminium Profile with Fluted Glass, Smooth Finish , Soft Close | H12: , Hettich Veyosis or Hafele Eqv, Greenlam , Century lam , Merino, Carcass -Century Bond or Green OptimaG / Shutter - CNR Aluminium Profile Shutters | J12: 2450 | L12: =J12+K12 -> 2450 | M12: 0.25 | N12: =L12*M12 -> 612.5 | O12: =L12+N12 -> 3062.5
A13: Mid Premium | B13: Modular | C13: Wet / Exposed Area | D13: Base Storage, Wall Storage, Tall Storage, Wardrobe | E13: Carcass/shutter | F13: Core Material, Finish Material, Hinges | G13: Carcass Inner 1mm- BWP / Shutter - Plywood Border with Clear / Tinted Glass , Smooth Finish , Soft Close | H13: Hettich Veyosis or Hafele Eqv , , Greenlam , Century lam , Merino, Carcass / Shutter - Century Bond or Green OptimaG with Glass | J13: 2345 | L13: =J13+K13 -> 2345 | M13: 0.25 | N13: =L13*M13 -> 586.25 | O13: =L13+N13 -> 2931.25
A14: Mid Premium | B14: Modular | C14: Wet / Exposed Area | D14: Base Storage, Wall Storage, Tall Storage, Wardrobe | E14: Carcass/shutter | F14: Core Material, Finish Material, Hinges | G14: Carcass inner 1mm - BWP / Shutter - Plywood Border with Fluted Glass , Smooth Finish , Soft Close | H14: Hettich Veyosis or Hafele Eqv , , Greenlam , Century lam , Merino, Carcass / Shutter - Century Bond or Green OptimaG with Glass | J14: 2465 | L14: =J14+K14 -> 2465 | M14: 0.25 | N14: =L14*M14 -> 616.25 | O14: =L14+N14 -> 3081.25
A15: Mid Premium | B15: Modular | C15: Wet / Exposed Area | D15: Base Storage, Wall Storage, Tall Storage, Wardrobe | E15: Carcass/shutter | F15: Core Material, Finish Material, Hinges | G15: Carcass Inner 1mm- BWP / Shutter - Black / Silver colour Aluminium Profile with Clear or Tinted Glass , Smooth Finish , Soft Close | H15: , Hettich Veyosis or Hafele Eqv, Greenlam , Century lam , Merino, Carcass -Century Bond or Green OptimaG / Shutter - CNR Aluminium Profile Shutters | J15: 2500 | L15: =J15+K15 -> 2500 | M15: 0.25 | N15: =L15*M15 -> 625 | O15: =L15+N15 -> 3125
A16: Mid Premium | B16: Modular | C16: Wet / Exposed Area | D16: Base Storage, Wall Storage, Tall Storage, Wardrobe | E16: Carcass/shutter | F16: Core Material, Finish Material, Hinges | G16: Carcass Inner 1mm - BWP / Shutter - Black / Silver colour Aluminium Profile with Fluted Glass, Smooth Finish , Soft Close | H16: , Hettich Veyosis or Hafele Eqv, Greenlam , Century lam , Merino, Carcass -Century Bond or Green OptimaG / Shutter - CNR Aluminium Profile Shutters | J16: 2600 | L16: =J16+K16 -> 2600 | M16: 0.25 | N16: =L16*M16 -> 650 | O16: =L16+N16 -> 3250
A17: Mid Premium | B17: Modular | C17: Wet / Exposed Area | D17: Base Storage, Wall Storage, Tall Storage, Wardrobe | E17: Carcass/shutter | F17: Core Material, Finish Material, Hinges | G17: Carcass Inner 1mm - BWP / Shutter - / Rose colour Aluminium Profile with Fluted Glass, Smooth Finish , Soft Close | H17: , Hettich Veyosis or Hafele Eqv, Greenlam , Century lam , Merino, Carcass -Century Bond or Green OptimaG / Shutter - CNR Aluminium Profile Shutters | J17: 2600 | L17: =J17+K17 -> 2600 | M17: 0.25 | N17: =L17*M17 -> 650 | O17: =L17+N17 -> 3250
A18: Mid Premium | B18: Modular | C18: Wet / Exposed Area | D18: Base Storage, Wall Storage, Tall Storage, Wardrobe | E18: Carcass/shutter | F18: Core Material, Finish Material, Hinges | G18: Carcass Inner 1mm- BWP / Shutter - / Rose colour Aluminium Profile with Clear or Tinted Glass, Smooth Finish , Soft Close | H18: , Hettich Veyosis or Hafele Eqv, Greenlam , Century lam , Merino, Carcass -Century Bond or Green OptimaG / Shutter - CNR Aluminium Profile Shutters | J18: 2700 | L18: =J18+K18 -> 2700 | M18: 0.25 | N18: =L18*M18 -> 675 | O18: =L18+N18 -> 3375
A19: Mid Premium | B19: Modular | C19: Wet / Exposed Area | D19: Curved Shape Base Storage unit | E19: Carcass/shutter | F19: Core Material, Finish Material, Hinges | G19: Carcass - BWP / Shutter - HDHMR Boilo, Smooth Finish , Soft Close | H19: Carcass - Century Bond or Green OptimaG / Shutter - Action TESA, Hettich Veyosis or Hafele Eqv , , Greenlam , Century lam , Merino | I19: Supply and installation of Curved Base storage unit with BWP Carcass, HDHMR Boilo Shutter, Smooth finish laminate and soft close hinges | J19: 2065 | L19: =J19+K19 -> 2065 | M19: 0.25 | N19: =L19*M19 -> 516.25 | O19: =L19+N19 -> 2581.25
A20: Mid Premium | B20: Modular | C20: Wet / Exposed Area | D20: Curved Shape Drawer Storage unit | E20: Carcass/shutter | F20: Core Material, Finish Material | G20: Carcass - BWP / Shutter - HDHMR Boilo, Smooth Finish | H20: Carcass - Century Bond or Green OptimaG / Shutter - Action TESA, Century lam , Merino , Greenlam | J20: 2065 | L20: =J20+K20 -> 2065 | M20: 0.25 | N20: =L20*M20 -> 516.25 | O20: =L20+N20 -> 2581.25
A21: Mid Premium | B21: Modular | C21: Wet / Exposed Area | D21: Tambour Storage | E21: Carcass | F21: Core Material, Finish Material | G21: CARCASS - BWP, Smooth Finish | H21: Carcass - Century Bond or Green OptimaG, Greenlam, Century lam , Merino | J21: 1465 | L21: =J21+K21 -> 1465 | M21: 0.25 | N21: =L21*M21 -> 366.25 | O21: =L21+N21 -> 1831.25
A22: Mid Premium | B22: Modular | C22: Wet / Exposed Area | D22: Open Unit - Inner 1mm | E22: Carcass | F22: Core Material, Finish Material | G22: CARCASS - BWP, Smooth Finish | H22: Carcass - Century Bond or Green OptimaG, Greenlam, Century lam , Merino | I22: Supply and installation of Open unit - Inner 1mm with BWP ply frame and Smooth finish laminate | J22: 1715 | L22: =J22+K22 -> 1715 | M22: 0.25 | N22: =L22*M22 -> 428.75 | O22: =L22+N22 -> 2143.75
A23: Mid Premium | B23: Modular | C23: Wet / Exposed Area | D23: Loft | E23: Frame and Shutter | F23: Core Material, Finish Material, Hinges | G23: Smooth Finish, Soft Close, Frame - BWP / Shutter - HDHMR Boilo | H23: Hettich Veyosis or Hafele Eqv , , Greenlam , Century lam , Merino, Frame- Century Bond or Green OptimaG / Shutter - Action TESA, | J23: 958 | L23: =J23+K23 -> 958 | M23: 0.25 | N23: =L23*M23 -> 239.5 | O23: =L23+N23 -> 1197.5
A24: Mid Premium | B24: Modular | C24: Wet / Exposed Area | D24: Ledge | E24: Ledge -25mm | F24: Finish Material, Core Material | G24: Smooth Finish , CARCASS - BWP | H24: Ledge - Century Bond or Green OptimaG, Greenlam , Century lam , Merino | I24: Supply and installation of Ledge with 25mm Ledge BWP and Smooth Finish Laminate | J24: 875 | L24: =J24+K24 -> 875 | M24: 0.25 | N24: =L24*M24 -> 218.75 | O24: =L24+N24 -> 1093.75
A25: Mid Premium | B25: Modular | C25: Wet / Exposed Area | D25: Ledge | E25: Ledge -36mm | F25: Finish Material, Core Material | G25: Smooth Finish , CARCASS - BWP | H25: Ledge - Century Bond or Green OptimaG, Greenlam , Century lam , Merino | I25: Supply and installation of Ledge with 36mm Ledge BWP and Smooth Finish Laminate | J25: 875 | L25: =J25+K25 -> 875 | M25: 0.25 | N25: =L25*M25 -> 218.75 | O25: =L25+N25 -> 1093.75
A26: Mid Premium | B26: Modular | C26: Wet / Exposed Area | D26: Ledge | E26: Ledge -50mm | F26: Finish Material, Core Material | G26: Smooth Finish , CARCASS - BWP | H26: Ledge - Century Bond or Green OptimaG, Greenlam , Century lam , Merino | I26: Supply and installation of Ledge with 50mm Ledge BWP and Smooth Finish Laminate | J26: 1025 | L26: =J26+K26 -> 1025 | M26: 0.25 | N26: =L26*M26 -> 256.25 | O26: =L26+N26 -> 1281.25
A27: Mid Premium | B27: Modular | C27: Wet / Exposed Area | D27: Partition | E27: Partition -75mm | F27: Finish Material, Core Material | G27: Smooth Finish , CARCASS - BWP | H27: Century Bond or Green OptimaG , Greenlam , Century lam , Merino | I27: Supply and installation of Ledge with 75mm Ledge BWP and Smooth Finish Laminate | J27: 1675 | L27: =J27+K27 -> 1675 | M27: 0.25 | N27: =L27*M27 -> 418.75 | O27: =L27+N27 -> 2093.75
A28: Mid Premium | B28: Modular | C28: Wet / Exposed Area | D28: Panel | E28: Curved Shape Panel | F28: Finish Material, Core Material | G28: Smooth Finish , CARCASS - BWP | H28: Century Bond or Green OptimaG, Century lam , Greenlam , Merino | I28: Supply and installation of Curved Wall Panel with BWP Ply Frame, Smooth Finish laminate | J28: 1008 | L28: =J28+K28 -> 1008 | M28: 0.25 | N28: =L28*M28 -> 252 | O28: =L28+N28 -> 1260
A29: Mid Premium | B29: Modular | C29: Wet / Exposed Area | D29: Panel | E29: Wallpanel , pelmet , Ceiling Panel , Base panel / Side panel | F29: Finish Material, Core Material | G29: Smooth Finish , CARCASS - BWP | H29: Century Bond or Green OptimaG, Century lam , Greenlam , Merino | I29: Supply and installation of Wall Panel with BWP Ply Frame, Smooth Finish laminate | J29: 1050 | L29: =J29+K29 -> 1050 | M29: 0.25 | N29: =L29*M29 -> 262.5 | O29: =L29+N29 -> 1312.5
I30: Supply and installation of Pelmet Panel with BWP Ply Frame, Smooth Finish laminate
I31: Supply and installation of Jam Panel with BWP Ply Frame, Smooth Finish laminate
I32: Supply and installation of Ceiling Panel with BWP Ply Frame, Smooth Finish laminate
I33: Supply and installation of Base Panel with BWP Ply Frame, Smooth Finish laminate
L34: =J34+K34 -> 0 | M34: 0.25 | N34: =L34*M34 -> 0 | O34: =L34+N34 -> 0
A35: GLOSSY FINISH | L35: =J35+K35 -> 0 | M35: 0.25 | N35: =L35*M35 -> 0 | O35: =L35+N35 -> 0
A36: Mid Premium | B36: Section | C36: Room Type | D36: Unit Type | E36: Panel type | F36: Category | G36: Material Type | H36: Brand | J36: Rate | L36: =J36+K36 -> #VALUE! | M36: 0.25 | N36: =L36*M36 -> #VALUE! | O36: =L36+N36 -> #VALUE!
A37: Mid Premium | B37: Modular | C37: Wet / Exposed Area | D37: Base Storage, Wall Storage, Tall Storage, Wardrobe | E37: Carcass/shutter | F37: Core Material, Finish Material, Hinges | G37: Carcass - BWP / Shutter - HDHMR Boilo, Glossy Finish, Soft Close | H37: Carcass - Century Bond or Green OptimaG / Shutter - Action TESA, Hettich Veyosis or Hafele Eqv , , Greenlam , Century lam , Merino | I37: Supply and installation of Base storage unit with BWP Carcass, HDHMR Boilo Shutter, Glossy finish laminate and soft close hinges | J37: =J3+50 -> 1765 | L37: =J37+K37 -> 1765 | M37: 0.25 | N37: =L37*M37 -> 441.25 | O37: =L37+N37 -> 2206.25
I38: Supply and installation of Wall storage unit with BWP Carcass, HDHMR Boilo Shutter, Glossy finish laminate and soft close hinges
I39: Supply and installation of Tall storage unit with BWP Carcass, HDHMR Boilo Shutter, Glossy finish laminate and soft close hinges
I40: Supply and installation of Wardrobe with BWP Carcass, HDHMR Boilo Shutter, Glossy finish laminate and soft close hinges
...

Sheet Luxury
A1: Project Type | B1: Section | C1: Room Type | D1: Unit Type | E1: Panel type | F1: Category | G1: Material Type | H1: Brand | J1: Rate | K1: Hinges Blum | L1: Basic Value | M1: Mark up | N1: Margin | O1: Selling Price
A2: SMOOTH FINISH
A3: Mid Premium | B3: Modular | C3: Wet / Exposed Area | D3: Base Storage, Wall Storage, Tall Storage, Wardrobe | E3: Carcass/shutter | F3: Core Material, Finish Material, Hinges | G3: Carcass - BWP / Shutter - HDHMR Boilo, Smooth Finish, Soft Close | H3: Carcass - Century ClubPrime or Green Gold / Shutter - Action TESA, Blum , , Royal Crown , Royal Touche , | I3: Supply and installation of Base storage unit with BWP Carcass, HDHMR Boilo Shutter, Smooth Finish laminate and soft close hinges | J3: 1790 | L3: =J3+K3 -> 1790 | M3: 0.25 | N3: =L3*M3 -> 447.5 | O3: =L3+N3 -> 2237.5
I4: Supply and installation of Wall storage unit with BWP Carcass, HDHMR Boilo Shutter, Smooth finish laminate and soft close hinges
I5: Supply and installation of Tall storage unit with BWP Carcass, HDHMR Boilo Shutter, Smooth finish laminate and soft close hinges
I6: Supply and installation of Wardrobe with BWP Carcass, HDHMR Boilo Shutter, Smooth finish laminate and soft close hinges
A7: Mid Premium | B7: Modular | C7: Wet / Exposed Area | D7: Base Storage, Wall Storage, Tall Storage, Wardrobe | E7: Carcass/shutter | F7: Core Material, Finish Material, Hinges | G7: Carcass - BWP / Shutter - Plywood Border with Clear / Tinted Glass , Soft Close, Smooth Finish | H7: Blum , , Royal Crown , Royal Touche , , Carcass / Shutter - Century ClubPrime or Green Gold with Glass | J7: 2170 | L7: =J7+K7 -> 2170 | M7: 0.25 | N7: =L7*M7 -> 542.5 | O7: =L7+N7 -> 2712.5
A8: Mid Premium | B8: Modular | C8: Wet / Exposed Area | D8: Base Storage, Wall Storage, Tall Storage, Wardrobe | E8: Carcass/shutter | F8: Core Material, Finish Material, Hinges | G8: Carcass - BWP / Shutter - Plywood Border with Fluted Glass , Smooth Finish , Soft Close | H8: Blum , , Royal Crown , Royal Touche , , Carcass / Shutter - Century ClubPrime or Green Gold with Glass | J8: 2290 | L8: =J8+K8 -> 2290 | M8: 0.25 | N8: =L8*M8 -> 572.5 | O8: =L8+N8 -> 2862.5
A9: Mid Premium | B9: Modular | C9: Wet / Exposed Area | D9: Base Storage, Wall Storage, Tall Storage, Wardrobe | E9: Carcass/shutter | F9: Core Material, Finish Material, Hinges | G9: Carcass - BWP / Shutter - Black / Silver colour Aluminium Profile with Clear or Tinted Glass, Smooth Finish , Soft Close | H9: , Blum, Royal Crown , Royal Touche , , Carcass -Century ClubPrime or Green Gold / Shutter - CNR Aluminium Profile Shutters | J9: 2325 | L9: =J9+K9 -> 2325 | M9: 0.25 | N9: =L9*M9 -> 581.25 | O9: =L9+N9 -> 2906.25
A10: Mid Premium | B10: Modular | C10: Wet / Exposed Area | D10: Base Storage, Wall Storage, Tall Storage, Wardrobe | E10: Carcass/shutter | F10: Core Material, Finish Material, Hinges | G10: Carcass - BWP / Shutter - Black / Silver colour Aluminium Profile with Fluted Glass, Smooth Finish , Soft Close | H10: , Blum, Royal Crown , Royal Touche , , Carcass -Century ClubPrime or Green Gold / Shutter - CNR Aluminium Profile Shutters | J10: 2425 | L10: =J10+K10 -> 2425 | M10: 0.25 | N10: =L10*M10 -> 606.25 | O10: =L10+N10 -> 3031.25
A11: Mid Premium | B11: Modular | C11: Wet / Exposed Area | D11: Base Storage, Wall Storage, Tall Storage, Wardrobe | E11: Carcass/shutter | F11: Core Material, Finish Material, Hinges | G11: Carcass - BWP / Shutter - / Rose colour Aluminium Profile with Clear or Tinted Glass, Soft Close, Smooth Finish | H11: , Blum, Royal Crown , Royal Touche , , Carcass -Century ClubPrime or Green Gold / Shutter - CNR Aluminium Profile Shutters | J11: 2425 | L11: =J11+K11 -> 2425 | M11: 0.25 | N11: =L11*M11 -> 606.25 | O11: =L11+N11 -> 3031.25
A12: Mid Premium | B12: Modular | C12: Wet / Exposed Area | D12: Base Storage, Wall Storage, Tall Storage, Wardrobe | E12: Carcass/shutter | F12: Core Material, Finish Material, Hinges | G12: Carcass - BWP / Shutter - / Rose colour Aluminium Profile with Fluted Glass, Smooth Finish , Soft Close | H12: , Blum, Royal Crown , Royal Touche , , Carcass -Century ClubPrime or Green Gold / Shutter - CNR Aluminium Profile Shutters | J12: 2525 | L12: =J12+K12 -> 2525 | M12: 0.25 | N12: =L12*M12 -> 631.25 | O12: =L12+N12 -> 3156.25
A13: Mid Premium | B13: Modular | C13: Wet / Exposed Area | D13: Base Storage, Wall Storage, Tall Storage, Wardrobe | E13: Carcass/shutter | F13: Core Material, Finish Material, Hinges | G13: Carcass Inner 1mm- BWP / Shutter - Plywood Border with Clear / Tinted Glass , Smooth Finish , Soft Close | H13: Blum , , Royal Crown , Royal Touche , , Carcass / Shutter - Century ClubPrime or Green Gold with Glass | J13: 2420 | L13: =J13+K13 -> 2420 | M13: 0.25 | N13: =L13*M13 -> 605 | O13: =L13+N13 -> 3025
A14: Mid Premium | B14: Modular | C14: Wet / Exposed Area | D14: Base Storage, Wall Storage, Tall Storage, Wardrobe | E14: Carcass/shutter | F14: Core Material, Finish Material, Hinges | G14: Carcass inner 1mm - BWP / Shutter - Plywood Border with Fluted Glass , Smooth Finish , Soft Close | H14: Blum , , Royal Crown , Royal Touche , , Carcass / Shutter - Century ClubPrime or Green Gold with Glass | J14: 2540 | L14: =J14+K14 -> 2540 | M14: 0.25 | N14: =L14*M14 -> 635 | O14: =L14+N14 -> 3175
A15: Mid Premium | B15: Modular | C15: Wet / Exposed Area | D15: Base Storage, Wall Storage, Tall Storage, Wardrobe | E15: Carcass/shutter | F15: Core Material, Finish Material, Hinges | G15: Carcass Inner 1mm- BWP / Shutter - Black / Silver colour Aluminium Profile with Clear or Tinted Glass , Smooth Finish , Soft Close | H15: , Blum, Royal Crown , Royal Touche , , Carcass -Century ClubPrime or Green Gold / Shutter - CNR Aluminium Profile Shutters | J15: 2575 | L15: =J15+K15 -> 2575 | M15: 0.25 | N15: =L15*M15 -> 643.75 | O15: =L15+N15 -> 3218.75
A16: Mid Premium | B16: Modular | C16: Wet / Exposed Area | D16: Base Storage, Wall Storage, Tall Storage, Wardrobe | E16: Carcass/shutter | F16: Core Material, Finish Material, Hinges | G16: Carcass Inner 1mm - BWP / Shutter - Black / Silver colour Aluminium Profile with Fluted Glass, Smooth Finish , Soft Close | H16: , Blum, Royal Crown , Royal Touche , , Carcass -Century ClubPrime or Green Gold / Shutter - CNR Aluminium Profile Shutters | J16: 2675 | L16: =J16+K16 -> 2675 | M16: 0.25 | N16: =L16*M16 -> 668.75 | O16: =L16+N16 -> 3343.75
A17: Mid Premium | B17: Modular | C17: Wet / Exposed Area | D17: Base Storage, Wall Storage, Tall Storage, Wardrobe | E17: Carcass/shutter | F17: Core Material, Finish Material, Hinges | G17: Carcass Inner 1mm - BWP / Shutter - / Rose colour Aluminium Profile with Fluted Glass, Smooth Finish , Soft Close | H17: , Blum, Royal Crown , Royal Touche , , Carcass -Century ClubPrime or Green Gold / Shutter - CNR Aluminium Profile Shutters | I17: Supply and installation of Base storage - Inner 1mm unit with BWP Carcass, Black/Silver Aluminium Profile with Clear/Tinted Glass Shutter, Smooth laminate and soft close hinges | J17: 2675 | L17: =J17+K17 -> 2675 | M17: 0.25 | N17: =L17*M17 -> 668.75 | O17: =L17+N17 -> 3343.75
I18: Supply and installation of Wall storage - Inner 1mm unit with BWP Carcass, Black/Silver Aluminium Profile with Clear/Tinted Glass Shutter, Smooth laminate and soft close hinges
I19: Supply and installation of Tall storage - Inner 1mm unit with BWP Carcass, Black/Silver Aluminium Profile with Clear/Tinted Glass Shutter, Smooth laminate and soft close hinges
I20: Supply and installation of Wardrobe - Inner 1mm unit with BWP Carcass, Black/Silver Aluminium Profile with Clear/Tinted Glass Shutter, Smooth laminate and soft close hinges
A21: Mid Premium | B21: Modular | C21: Wet / Exposed Area | D21: Base Storage, Wall Storage, Tall Storage, Wardrobe | E21: Carcass/shutter | F21: Core Material, Finish Material, Hinges | G21: Carcass Inner 1mm- BWP / Shutter - / Rose colour Aluminium Profile with Clear or Tinted Glass, Smooth Finish , Soft Close | H21: , Blum, Royal Crown , Royal Touche , , Carcass -Century ClubPrime or Green Gold / Shutter - CNR Aluminium Profile Shutters | J21: 2775 | L21: =J21+K21 -> 2775 | M21: 0.25 | N21: =L21*M21 -> 693.75 | O21: =L21+N21 -> 3468.75
A22: Mid Premium | B22: Modular | C22: Wet / Exposed Area | D22: Curved Shape Base Storage unit | E22: Carcass/shutter | F22: Core Material, Finish Material, Hinges | G22: Carcass - BWP / Shutter - HDHMR Boilo, Smooth Finish , Soft Close | H22: Carcass - Century ClubPrime or Green Gold / Shutter - Action TESA, Blum , , Royal Crown , Royal Touche , | J22: 2140 | L22: =J22+K22 -> 2140 | M22: 0.25 | N22: =L22*M22 -> 535 | O22: =L22+N22 -> 2675
A23: Mid Premium | B23: Modular | C23: Wet / Exposed Area | D23: Curved Shape Drawer Storage unit | E23: Carcass/shutter | F23: Core Material, Finish Material | G23: Carcass - BWP / Shutter - HDHMR Boilo, Smooth Finish | H23: Carcass - Century ClubPrime or Green Gold / Shutter - Action TESA, Royal Touche , , Royal Crown | J23: 2140 | L23: =J23+K23 -> 2140 | M23: 0.25 | N23: =L23*M23 -> 535 | O23: =L23+N23 -> 2675
A24: Mid Premium | B24: Modular | C24: Wet / Exposed Area | D24: Tambour Storage | E24: Carcass | F24: Core Material, Finish Material | G24: CARCASS - BWP, Smooth Finish | H24: Carcass - Century ClubPrime or Green Gold , Royal Crown, Royal Touche , | J24: 1540 | L24: =J24+K24 -> 1540 | M24: 0.25 | N24: =L24*M24 -> 385 | O24: =L24+N24 -> 1925
A25: Mid Premium | B25: Modular | C25: Wet / Exposed Area | D25: Open Unit - Inner 1mm | E25: Carcass | F25: Core Material, Finish Material | G25: CARCASS - BWP, Smooth Finish | H25: Carcass - Century ClubPrime or Green Gold , Royal Crown, Royal Touche , | I25: Supply and installation of Open unit - Inner 1mm with BWP ply frame and Smooth finish laminate | J25: 1790 | L25: =J25+K25 -> 1790 | M25: 0.25 | N25: =L25*M25 -> 447.5 | O25: =L25+N25 -> 2237.5
A26: Mid Premium | B26: Modular | C26: Wet / Exposed Area | D26: Loft | E26: Frame and Shutter | F26: Core Material, Finish Material, Hinges | G26: Smooth Finish, Soft Close, Frame - BWP / Shutter - HDHMR Boilo | H26: Blum , , Royal Crown , Royal Touche , , Frame- Century ClubPrime or Green Gold / Shutter - Action TESA, | I26: Supply and installation of Loft Frame and Shutter unit with BWP Frame, HDHMR Boilo Shutter, Smooth laminate and Soft Close hinges | J26: 1033 | L26: =J26+K26 -> 1033 | M26: 0.25 | N26: =L26*M26 -> 258.25 | O26: =L26+N26 -> 1291.25
A27: Mid Premium | B27: Modular | C27: Wet / Exposed Area | D27: Ledge | E27: Ledge -25mm | F27: Finish Material, Core Material | G27: Smooth Finish , CARCASS - BWP | H27: Ledge - Century ClubPrime or Green Gold , Royal Crown , Royal Touche , | I27: Supply and installation of Ledge with 25mm Ledge BWP and Smooth Laminate | J27: 950 | L27: =J27+K27 -> 950 | M27: 0.25 | N27: =L27*M27 -> 237.5 | O27: =L27+N27 -> 1187.5
A28: Mid Premium | B28: Modular | C28: Wet / Exposed Area | D28: Ledge | E28: Ledge -36mm | F28: Finish Material, Core Material | G28: Smooth Finish , CARCASS - BWP | H28: Ledge - Century ClubPrime or Green Gold , Royal Crown , Royal Touche , | I28: Supply and installation of Ledge with 36mm Ledge BWP and Smooth Laminate | J28: 950 | L28: =J28+K28 -> 950 | M28: 0.25 | N28: =L28*M28 -> 237.5 | O28: =L28+N28 -> 1187.5
A29: Mid Premium | B29: Modular | C29: Wet / Exposed Area | D29: Ledge | E29: Ledge -50mm | F29: Finish Material, Core Material | G29: Smooth Finish , CARCASS - BWP | H29: Ledge - Century ClubPrime or Green Gold , Royal Crown , Royal Touche , | I29: Supply and installation of Ledge with 50mm Ledge BWP and Smooth Laminate | J29: 1100 | L29: =J29+K29 -> 1100 | M29: 0.25 | N29: =L29*M29 -> 275 | O29: =L29+N29 -> 1375
A30: Mid Premium | B30: Modular | C30: Wet / Exposed Area | D30: Partition | E30: Partition -75mm | F30: Finish Material, Core Material | G30: Smooth Finish , CARCASS - BWP | H30: Century ClubPrime or Green Gold , Royal Crown , Royal Touche , | I30: Supply and installation of Partition - 75mm with BWP Ply Frame, Smooth laminate | J30: 1750 | L30: =J30+K30 -> 1750 | M30: 0.25 | N30: =L30*M30 -> 437.5 | O30: =L30+N30 -> 2187.5
A31: Mid Premium | B31: Modular | C31: Wet / Exposed Area | D31: Panel | E31: Curved Shape Panel | F31: Finish Material, Core Material | G31: Smooth Finish , CARCASS - BWP | H31: Century ClubPrime or Green Gold , Royal Touche , Royal Crown , | J31: 1083 | L31: =J31+K31 -> 1083 | M31: 0.25 | N31: =L31*M31 -> 270.75 | O31: =L31+N31 -> 1353.75
A32: Mid Premium | B32: Modular | C32: Wet / Exposed Area | D32: Panel | E32: Wallpanel , pelmet , Ceiling Panel , Base panel / Side panel | F32: Finish Material, Core Material | G32: Smooth Finish , CARCASS - BWP | H32: Century ClubPrime or Green Gold , Royal Touche , Royal Crown , | I32: Supply and installation of Wall Panel with BWP Ply Frame, Smooth Finish laminate | J32: 1125 | L32: =J32+K32 -> 1125 | M32: 0.25 | N32: =L32*M32 -> 281.25 | O32: =L32+N32 -> 1406.25
I33: Supply and installation of Pelmet Panel with BWP Ply Frame, Smooth Finish laminate
I34: Supply and installation of Jam Panel with BWP Ply Frame, Smooth Finish laminate
I35: Supply and installation of Ceiling Panel with BWP Ply Frame, Smooth Finish laminate
I36: Supply and installation of Base Panel with BWP Ply Frame, Smooth Finish laminate
L37: =J37+K37 -> 0 | M37: 0.25 | N37: =L37*M37 -> 0 | O37: =L37+N37 -> 0
A38: GLOSSY FINISH | L38: =J38+K38 -> 0 | M38: 0.25 | N38: =L38*M38 -> 0 | O38: =L38+N38 -> 0
A39: Mid Premium | B39: Section | C39: Room Type | D39: Unit Type | E39: Panel type | F39: Category | G39: Material Type | H39: Brand | J39: Rate | L39: =J39+K39 -> #VALUE! | M39: 0.25 | N39: =L39*M39 -> #VALUE! | O39: =L39+N39 -> #VALUE!
A40: Mid Premium | B40: Modular | C40: Wet / Exposed Area | D40: Base Storage, Wall Storage, Tall Storage, Wardrobe | E40: Carcass/shutter | F40: Core Material, Finish Material, Hinges | G40: Carcass - BWP / Shutter - HDHMR Boilo, Glossy Finish, Soft Close | H40: Carcass - Century ClubPrime or Green Gold / Shutter - Action TESA, Blum , , Royal Crown , Royal Touche , | J40: 1840 | L40: =J40+K40 -> 1840 | M40: 0.25 | N40: =L40*M40 -> 460 | O40: =L40+N40 -> 2300
...

Sheet GQ 1
A2: No | B2: Description | C2: Length (Ft) | D2: Height | E2: Qty (sqft) | F2: Unit | G2: Length (mm) | H2: Height | I2: Unit | J2: Rate | K2: Quantity | L2: Amount
B4: Modular Work
B5: Living room
B6: =Economy!I46 -> Supply and installation of Base storage unit with MR Premium Carcass, HDF Shutter, Smooth finish laminate and soft close hinges | C6: 4 | D6: 1.5 | E6: =C6*D6 -> 6 | F6: Sft | G6: =C6*300 -> 1200 | H6: =D6*300 -> 450 | I6: mm | J6: =Economy!M46 -> 1718.75 | K6: 1 | L6: =K6*J6*E6 -> 10312.5
